Traceback (most recent call last):
  File "/home/getachew/anaconda3/envs/datavis/lib/python3.9/site-packages/jupyter_cache/executors/utils.py", line 51, in single_nb_execution
    executenb(
  File "/home/getachew/anaconda3/envs/datavis/lib/python3.9/site-packages/nbclient/client.py", line 1204, in execute
    return NotebookClient(nb=nb, resources=resources, km=km, **kwargs).execute()
  File "/home/getachew/anaconda3/envs/datavis/lib/python3.9/site-packages/nbclient/util.py", line 84, in wrapped
    return just_run(coro(*args, **kwargs))
  File "/home/getachew/anaconda3/envs/datavis/lib/python3.9/site-packages/nbclient/util.py", line 62, in just_run
    return loop.run_until_complete(coro)
  File "/home/getachew/anaconda3/envs/datavis/lib/python3.9/asyncio/base_events.py", line 647, in run_until_complete
    return future.result()
  File "/home/getachew/anaconda3/envs/datavis/lib/python3.9/site-packages/nbclient/client.py", line 663, in async_execute
    await self.async_execute_cell(
  File "/home/getachew/anaconda3/envs/datavis/lib/python3.9/site-packages/nbclient/client.py", line 965, in async_execute_cell
    await self._check_raise_for_error(cell, cell_index, exec_reply)
  File "/home/getachew/anaconda3/envs/datavis/lib/python3.9/site-packages/nbclient/client.py", line 862, in _check_raise_for_error
    raise CellExecutionError.from_cell_and_msg(cell, exec_reply_content)
nbclient.exceptions.CellExecutionError: An error occurred while executing the following cell:
------------------
if __name__ == '__main__':
    app.run_server(mode='inline', port=8052)
------------------

[0;31m---------------------------------------------------------------------------[0m
[0;31mOSError[0m                                   Traceback (most recent call last)
Cell [0;32mIn[8], line 2[0m
[1;32m      1[0m [38;5;28;01mif[39;00m [38;5;18m__name__[39m [38;5;241m==[39m [38;5;124m'[39m[38;5;124m__main__[39m[38;5;124m'[39m:
[0;32m----> 2[0m     [43mapp[49m[38;5;241;43m.[39;49m[43mrun_server[49m[43m([49m[43mmode[49m[38;5;241;43m=[39;49m[38;5;124;43m'[39;49m[38;5;124;43minline[39;49m[38;5;124;43m'[39;49m[43m,[49m[43m [49m[43mport[49m[38;5;241;43m=[39;49m[38;5;241;43m8052[39;49m[43m)[49m

File [0;32m~/anaconda3/envs/datavis/lib/python3.9/site-packages/jupyter_dash/jupyter_app.py:339[0m, in [0;36mJupyterDash.run_server[0;34m(self, mode, width, height, inline_exceptions, **kwargs)[0m
[1;32m    329[0m         url [38;5;241m=[39m [38;5;124m"[39m[38;5;124mhttp://[39m[38;5;132;01m{host}[39;00m[38;5;124m:[39m[38;5;132;01m{port}[39;00m[38;5;124m"[39m[38;5;241m.[39mformat(
[1;32m    330[0m             host[38;5;241m=[39mhost, port[38;5;241m=[39mport, token[38;5;241m=[39mJupyterDash[38;5;241m.[39m_token
[1;32m    331[0m         )
[1;32m    332[0m         [38;5;28;01mraise[39;00m [38;5;167;01mOSError[39;00m(
[1;32m    333[0m             [38;5;124m"[39m[38;5;124mAddress [39m[38;5;124m'[39m[38;5;132;01m{url}[39;00m[38;5;124m'[39m[38;5;124m already in use.[39m[38;5;130;01m\n[39;00m[38;5;124m"[39m
[1;32m    334[0m             [38;5;124m"[39m[38;5;124m    Try passing a different port to run_server.[39m[38;5;124m"[39m[38;5;241m.[39mformat(
[1;32m    335[0m                 url[38;5;241m=[39murl
[1;32m    336[0m             )
[1;32m    337[0m         )
[0;32m--> 339[0m [43mwait_for_app[49m[43m([49m[43m)[49m
[1;32m    341[0m [38;5;28;01mif[39;00m JupyterDash[38;5;241m.[39m_in_colab:
[1;32m    342[0m     [38;5;28mself[39m[38;5;241m.[39m_display_in_colab(dashboard_url, port, mode, width, height)

File [0;32m~/anaconda3/envs/datavis/lib/python3.9/site-packages/retrying.py:56[0m, in [0;36mretry.<locals>.wrap.<locals>.wrapped_f[0;34m(*args, **kw)[0m
[1;32m     54[0m [38;5;129m@six[39m[38;5;241m.[39mwraps(f)
[1;32m     55[0m [38;5;28;01mdef[39;00m [38;5;21mwrapped_f[39m([38;5;241m*[39margs, [38;5;241m*[39m[38;5;241m*[39mkw):
[0;32m---> 56[0m     [38;5;28;01mreturn[39;00m [43mRetrying[49m[43m([49m[38;5;241;43m*[39;49m[43mdargs[49m[43m,[49m[43m [49m[38;5;241;43m*[39;49m[38;5;241;43m*[39;49m[43mdkw[49m[43m)[49m[38;5;241;43m.[39;49m[43mcall[49m[43m([49m[43mf[49m[43m,[49m[43m [49m[38;5;241;43m*[39;49m[43margs[49m[43m,[49m[43m [49m[38;5;241;43m*[39;49m[38;5;241;43m*[39;49m[43mkw[49m[43m)[49m

File [0;32m~/anaconda3/envs/datavis/lib/python3.9/site-packages/retrying.py:266[0m, in [0;36mRetrying.call[0;34m(self, fn, *args, **kwargs)[0m
[1;32m    263[0m [38;5;28;01mif[39;00m [38;5;28mself[39m[38;5;241m.[39mstop(attempt_number, delay_since_first_attempt_ms):
[1;32m    264[0m     [38;5;28;01mif[39;00m [38;5;129;01mnot[39;00m [38;5;28mself[39m[38;5;241m.[39m_wrap_exception [38;5;129;01mand[39;00m attempt[38;5;241m.[39mhas_exception:
[1;32m    265[0m         [38;5;66;03m# get() on an attempt with an exception should cause it to be raised, but raise just in case[39;00m
[0;32m--> 266[0m         [38;5;28;01mraise[39;00m [43mattempt[49m[38;5;241;43m.[39;49m[43mget[49m[43m([49m[43m)[49m
[1;32m    267[0m     [38;5;28;01melse[39;00m:
[1;32m    268[0m         [38;5;28;01mraise[39;00m RetryError(attempt)

File [0;32m~/anaconda3/envs/datavis/lib/python3.9/site-packages/retrying.py:301[0m, in [0;36mAttempt.get[0;34m(self, wrap_exception)[0m
[1;32m    299[0m         [38;5;28;01mraise[39;00m RetryError([38;5;28mself[39m)
[1;32m    300[0m     [38;5;28;01melse[39;00m:
[0;32m--> 301[0m         [43msix[49m[38;5;241;43m.[39;49m[43mreraise[49m[43m([49m[38;5;28;43mself[39;49m[38;5;241;43m.[39;49m[43mvalue[49m[43m[[49m[38;5;241;43m0[39;49m[43m][49m[43m,[49m[43m [49m[38;5;28;43mself[39;49m[38;5;241;43m.[39;49m[43mvalue[49m[43m[[49m[38;5;241;43m1[39;49m[43m][49m[43m,[49m[43m [49m[38;5;28;43mself[39;49m[38;5;241;43m.[39;49m[43mvalue[49m[43m[[49m[38;5;241;43m2[39;49m[43m][49m[43m)[49m
[1;32m    302[0m [38;5;28;01melse[39;00m:
[1;32m    303[0m     [38;5;28;01mreturn[39;00m [38;5;28mself[39m[38;5;241m.[39mvalue

File [0;32m~/anaconda3/envs/datavis/lib/python3.9/site-packages/six.py:719[0m, in [0;36mreraise[0;34m(tp, value, tb)[0m
[1;32m    717[0m     [38;5;28;01mif[39;00m value[38;5;241m.[39m__traceback__ [38;5;129;01mis[39;00m [38;5;129;01mnot[39;00m tb:
[1;32m    718[0m         [38;5;28;01mraise[39;00m value[38;5;241m.[39mwith_traceback(tb)
[0;32m--> 719[0m     [38;5;28;01mraise[39;00m value
[1;32m    720[0m [38;5;28;01mfinally[39;00m:
[1;32m    721[0m     value [38;5;241m=[39m [38;5;28;01mNone[39;00m

File [0;32m~/anaconda3/envs/datavis/lib/python3.9/site-packages/retrying.py:251[0m, in [0;36mRetrying.call[0;34m(self, fn, *args, **kwargs)[0m
[1;32m    248[0m     [38;5;28mself[39m[38;5;241m.[39m_before_attempts(attempt_number)
[1;32m    250[0m [38;5;28;01mtry[39;00m:
[0;32m--> 251[0m     attempt [38;5;241m=[39m Attempt([43mfn[49m[43m([49m[38;5;241;43m*[39;49m[43margs[49m[43m,[49m[43m [49m[38;5;241;43m*[39;49m[38;5;241;43m*[39;49m[43mkwargs[49m[43m)[49m, attempt_number, [38;5;28;01mFalse[39;00m)
[1;32m    252[0m [38;5;28;01mexcept[39;00m:
[1;32m    253[0m     tb [38;5;241m=[39m sys[38;5;241m.[39mexc_info()

File [0;32m~/anaconda3/envs/datavis/lib/python3.9/site-packages/jupyter_dash/jupyter_app.py:332[0m, in [0;36mJupyterDash.run_server.<locals>.wait_for_app[0;34m()[0m
[1;32m    328[0m [38;5;28;01mif[39;00m res [38;5;241m!=[39m [38;5;124m"[39m[38;5;124mAlive[39m[38;5;124m"[39m:
[1;32m    329[0m     url [38;5;241m=[39m [38;5;124m"[39m[38;5;124mhttp://[39m[38;5;132;01m{host}[39;00m[38;5;124m:[39m[38;5;132;01m{port}[39;00m[38;5;124m"[39m[38;5;241m.[39mformat(
[1;32m    330[0m         host[38;5;241m=[39mhost, port[38;5;241m=[39mport, token[38;5;241m=[39mJupyterDash[38;5;241m.[39m_token
[1;32m    331[0m     )
[0;32m--> 332[0m     [38;5;28;01mraise[39;00m [38;5;167;01mOSError[39;00m(
[1;32m    333[0m         [38;5;124m"[39m[38;5;124mAddress [39m[38;5;124m'[39m[38;5;132;01m{url}[39;00m[38;5;124m'[39m[38;5;124m already in use.[39m[38;5;130;01m\n[39;00m[38;5;124m"[39m
[1;32m    334[0m         [38;5;124m"[39m[38;5;124m    Try passing a different port to run_server.[39m[38;5;124m"[39m[38;5;241m.[39mformat(
[1;32m    335[0m             url[38;5;241m=[39murl
[1;32m    336[0m         )
[1;32m    337[0m     )

[0;31mOSError[0m: Address 'http://127.0.0.1:8052' already in use.
    Try passing a different port to run_server.
OSError: Address 'http://127.0.0.1:8052' already in use.
    Try passing a different port to run_server.

